<?xml version="1.0" encoding="utf-8"?>
<!-- This URDF was automatically created by SolidWorks to URDF Exporter! Originally created by Stephen Brawner (brawner@gmail.com) 
     Commit Version: 1.6.0-1-g15f4949  Build Version: 1.6.7594.29634
     For more information, please see http://wiki.ros.org/sw_urdf_exporter -->
<robot
  name="BRTIRUS1510A10kg.SLDASM">
  <link
    name="base_link">
    <inertial>
      <origin
        xyz="0.041987 -0.0096836 0.27247"
        rpy="0 0 0" />
      <mass
        value="239.98" />
      <inertia
        ixx="30.981"
        ixy="0.2359"
        ixz="-11.149"
        iyy="37.487"
        iyz="1.0005"
        izz="10.257" />
    </inertial>
    <visual>
      <origin
        xyz="0 0 0"
        rpy="0 0 0" />
      <geometry>
        <mesh
          filename="package://BRTIRUS1510A10kg.SLDASM/meshes/base_link.STL" />
      </geometry>
      <material
        name="">
        <color
          rgba="0.79216 0.81961 0.93333 1" />
      </material>
    </visual>
    <collision>
      <origin
        xyz="0 0 0"
        rpy="0 0 0" />
      <geometry>
        <mesh
          filename="package://BRTIRUS1510A10kg.SLDASM/meshes/base_link.STL" />
      </geometry>
    </collision>
  </link>
  <link
    name="Link_1">
    <inertial>
      <origin
        xyz="0.041987 -0.0096836 0.094469"
        rpy="0 0 0" />
      <mass
        value="239.98" />
      <inertia
        ixx="30.981"
        ixy="0.2359"
        ixz="-11.149"
        iyy="37.487"
        iyz="1.0005"
        izz="10.257" />
    </inertial>
    <visual>
      <origin
        xyz="0 0 0"
        rpy="0 0 0" />
      <geometry>
        <mesh
          filename="package://BRTIRUS1510A10kg.SLDASM/meshes/Link_1.STL" />
      </geometry>
      <material
        name="">
        <color
          rgba="0.79216 0.81961 0.93333 1" />
      </material>
    </visual>
    <collision>
      <origin
        xyz="0 0 0"
        rpy="0 0 0" />
      <geometry>
        <mesh
          filename="package://BRTIRUS1510A10kg.SLDASM/meshes/Link_1.STL" />
      </geometry>
    </collision>
  </link>
  <joint
    name="Jonit_1"
    type="revolute">
    <origin
      xyz="0 0 0.178"
      rpy="0 0 0" />
    <parent
      link="base_link" />
    <child
      link="Link_1" />
    <axis
      xyz="0 0 1" />
    <limit
      lower="-2.8798"
      upper="2.8798"
      effort="10"
      velocity="0" />
  </joint>
  <link
    name="Link_2">
    <inertial>
      <origin
        xyz="-0.12056 -0.12734 0.094816"
        rpy="0 0 0" />
      <mass
        value="239.98" />
      <inertia
        ixx="10.257"
        ixy="-11.149"
        ixz="1.0005"
        iyy="30.981"
        iyz="0.2359"
        izz="37.487" />
    </inertial>
    <visual>
      <origin
        xyz="0 0 0"
        rpy="0 0 0" />
      <geometry>
        <mesh
          filename="package://BRTIRUS1510A10kg.SLDASM/meshes/Link_2.STL" />
      </geometry>
      <material
        name="">
        <color
          rgba="0.75294 0.75294 0.75294 1" />
      </material>
    </visual>
    <collision>
      <origin
        xyz="0 0 0"
        rpy="0 0 0" />
      <geometry>
        <mesh
          filename="package://BRTIRUS1510A10kg.SLDASM/meshes/Link_2.STL" />
      </geometry>
    </collision>
  </link>
  <joint
    name="Joint_2"
    type="revolute">
    <origin
      xyz="0.16933 -0.1045 0.21503"
      rpy="1.5708 -1.5708 0" />
    <parent
      link="Link_1" />
    <child
      link="Link_2" />
    <axis
      xyz="0 0 -1" />
    <limit
      lower="-1.6581"
      upper="1.2217"
      effort="10"
      velocity="0" />
  </joint>
  <link
    name="Link_3">
    <inertial>
      <origin
        xyz="-0.77056 -0.12734 0.095816"
        rpy="0 0 0" />
      <mass
        value="239.98" />
      <inertia
        ixx="10.257"
        ixy="-11.149"
        ixz="1.0005"
        iyy="30.981"
        iyz="0.2359"
        izz="37.487" />
    </inertial>
    <visual>
      <origin
        xyz="0 0 0"
        rpy="0 0 0" />
      <geometry>
        <mesh
          filename="package://BRTIRUS1510A10kg.SLDASM/meshes/Link_3.STL" />
      </geometry>
      <material
        name="">
        <color
          rgba="0.75294 0.75294 0.75294 1" />
      </material>
    </visual>
    <collision>
      <origin
        xyz="0 0 0"
        rpy="0 0 0" />
      <geometry>
        <mesh
          filename="package://BRTIRUS1510A10kg.SLDASM/meshes/Link_3.STL" />
      </geometry>
    </collision>
  </link>
  <joint
    name="Jonit_3"
    type="fixed">
    <origin
      xyz="0.65 0 -0.001"
      rpy="0 0 0" />
    <parent
      link="Link_2" />
    <child
      link="Link_3" />
    <axis
      xyz="0 0 0" />
  </joint>
</robot>